labopb@criugm0279:~/git/task_stimuli$ python3 main.py --subject 01 --ses videogame_test  --fmri
pygame 1.9.4
Hello from the pygame community. https://www.pygame.org/contribute.html
Namespace(eyetracking=False, fmri=True, meg=False, session='videogame_test', subject='01')
[983.46666667 768.        ]
435.61
READY
Next task: <class 'src.tasks.video.VideoAudioCheckLoop'> : setup_video
16333.3571 	WARNING 	Monitor specification not found. Creating a temporary one...
16333.6624 	WARNING 	The size of the gamma ramp was reported as 0. This can mean that gamma settings have no effect. Proceeding with a default gamma ramp size.
16333.6629 	WARNING 	The size of the gamma ramp was reported as 0. This can mean that gamma settings have no effect. Proceeding with a default gamma ramp size.
skip
READY
Next task: <class 'src.tasks.task_base.Pause'> : Pause
skip
READY
Next task: <class 'src.tasks.videogame.VideoGame'> : ShinobiIIIReturnOfTheNinjaMaster-test
Next task: <class 'src.tasks.videogame.VideoGame'> : ShinobiIIIReturnOfTheNinjaMaster-test
Traceback (most recent call last):
  File "/home/labopb/.local/lib/python3.6/site-packages/pyglet/event.py", line 367, in dispatch_event
    if getattr(self, event_type)(*args):
TypeError: 'NoneType' object is not callable

During handling of the above exception, another exception occurred:

Traceback (most recent call last):
  File "/usr/lib/python3.6/inspect.py", line 1124, in getfullargspec
    sigcls=Signature)
  File "/usr/lib/python3.6/inspect.py", line 2191, in _signature_from_callable
    raise TypeError('{!r} is not a callable object'.format(obj))
TypeError: None is not a callable object

The above exception was the direct cause of the following exception:

Traceback (most recent call last):
  File "main.py", line 24, in <module>
    cli.main_loop(tasks, parsed.subject, parsed.session, parsed.eyetracking, parsed.fmri, parsed.meg)
  File "/home/labopb/git/task_stimuli/src/shared/cli.py", line 135, in main_loop
    exp_win.flip()
  File "/home/labopb/.local/lib/python3.6/site-packages/psychopy/visual/window.py", line 779, in flip
    self.backend.swapBuffers(flipThisFrame)
  File "/home/labopb/.local/lib/python3.6/site-packages/psychopy/visual/backends/pygletbackend.py", line 259, in swapBuffers
    self.winHandle.dispatch_events()
  File "/home/labopb/.local/lib/python3.6/site-packages/pyglet/window/xlib/__init__.py", line 881, in dispatch_events
    self.dispatch_platform_event(e)
  File "/home/labopb/.local/lib/python3.6/site-packages/pyglet/window/xlib/__init__.py", line 917, in dispatch_platform_event
    event_handler(e)
  File "/home/labopb/.local/lib/python3.6/site-packages/pyglet/window/xlib/__init__.py", line 1108, in _event_key
    return self._event_key_view(ev)
  File "/home/labopb/.local/lib/python3.6/site-packages/pyglet/window/xlib/__init__.py", line 1101, in _event_key_view
    self.dispatch_event('on_key_release', symbol, modifiers)
  File "/home/labopb/.local/lib/python3.6/site-packages/pyglet/window/__init__.py", line 1232, in dispatch_event
    if EventDispatcher.dispatch_event(self, *args) != False:
  File "/home/labopb/.local/lib/python3.6/site-packages/pyglet/event.py", line 371, in dispatch_event
    event_type, args, getattr(self, event_type))
  File "/home/labopb/.local/lib/python3.6/site-packages/pyglet/event.py", line 392, in _raise_dispatch_exception
    inspect.getargspec(handler)
  File "/usr/lib/python3.6/inspect.py", line 1078, in getargspec
    getfullargspec(func)
  File "/usr/lib/python3.6/inspect.py", line 1130, in getfullargspec
    raise TypeError('unsupported callable') from ex
TypeError: unsupported callable
labopb@criugm0279:~/git/task_stimuli$ python3 main.py --subject 01 --ses videogame_test  --fmri
pygame 1.9.4
Hello from the pygame community. https://www.pygame.org/contribute.html
Namespace(eyetracking=False, fmri=True, meg=False, session='videogame_test', subject='01')
[983.46666667 768.        ]
435.61
READY
Next task: <class 'src.tasks.video.VideoAudioCheckLoop'> : setup_video
17292.8077 	WARNING 	Monitor specification not found. Creating a temporary one...
17293.1032 	WARNING 	The size of the gamma ramp was reported as 0. This can mean that gamma settings have no effect. Proceeding with a default gamma ramp size.
17293.1036 	WARNING 	The size of the gamma ramp was reported as 0. This can mean that gamma settings have no effect. Proceeding with a default gamma ramp size.
skip
READY
Next task: <class 'src.tasks.task_base.Pause'> : Pause
skip
READY
Next task: <class 'src.tasks.videogame.VideoGame'> : ShinobiIIIReturnOfTheNinjaMaster-test
Traceback (most recent call last):
  File "/home/labopb/.local/lib/python3.6/site-packages/pyglet/event.py", line 367, in dispatch_event
    if getattr(self, event_type)(*args):
TypeError: 'NoneType' object is not callable

During handling of the above exception, another exception occurred:

Traceback (most recent call last):
  File "/usr/lib/python3.6/inspect.py", line 1124, in getfullargspec
    sigcls=Signature)
  File "/usr/lib/python3.6/inspect.py", line 2191, in _signature_from_callable
    raise TypeError('{!r} is not a callable object'.format(obj))
TypeError: None is not a callable object

The above exception was the direct cause of the following exception:

Traceback (most recent call last):
  File "main.py", line 24, in <module>
    cli.main_loop(tasks, parsed.subject, parsed.session, parsed.eyetracking, parsed.fmri, parsed.meg)
  File "/home/labopb/git/task_stimuli/src/shared/cli.py", line 135, in main_loop
    exp_win.flip()
  File "/home/labopb/.local/lib/python3.6/site-packages/psychopy/visual/window.py", line 779, in flip
    self.backend.swapBuffers(flipThisFrame)
  File "/home/labopb/.local/lib/python3.6/site-packages/psychopy/visual/backends/pygletbackend.py", line 259, in swapBuffers
    self.winHandle.dispatch_events()
  File "/home/labopb/.local/lib/python3.6/site-packages/pyglet/window/xlib/__init__.py", line 881, in dispatch_events
    self.dispatch_platform_event(e)
  File "/home/labopb/.local/lib/python3.6/site-packages/pyglet/window/xlib/__init__.py", line 917, in dispatch_platform_event
    event_handler(e)
  File "/home/labopb/.local/lib/python3.6/site-packages/pyglet/window/xlib/__init__.py", line 1108, in _event_key
    return self._event_key_view(ev)
  File "/home/labopb/.local/lib/python3.6/site-packages/pyglet/window/xlib/__init__.py", line 1101, in _event_key_view
    self.dispatch_event('on_key_release', symbol, modifiers)
  File "/home/labopb/.local/lib/python3.6/site-packages/pyglet/window/__init__.py", line 1232, in dispatch_event
    if EventDispatcher.dispatch_event(self, *args) != False:
  File "/home/labopb/.local/lib/python3.6/site-packages/pyglet/event.py", line 371, in dispatch_event
    event_type, args, getattr(self, event_type))
  File "/home/labopb/.local/lib/python3.6/site-packages/pyglet/event.py", line 392, in _raise_dispatch_exception
    inspect.getargspec(handler)
  File "/usr/lib/python3.6/inspect.py", line 1078, in getargspec
    getfullargspec(func)
  File "/usr/lib/python3.6/inspect.py", line 1130, in getfullargspec
    raise TypeError('unsupported callable') from ex
TypeError: unsupported callable
